<?xml version="1.0" ?>
<!-- =================================================================================== -->
<!-- |    This document was autogenerated by xacro from /home/enrico/catkin_ws/src/kairos_cartesio_config/robots/fb_kairos_ur5e_oem.urdf.xacro | -->
<!-- |    EDITING THIS FILE BY HAND IS NOT RECOMMENDED                                 | -->
<!-- =================================================================================== -->
<robot name="rb_kairos_ur10e">
  <!-- **************** -->
  <!-- KAIROS arguments -->
  <!-- **************** -->
  <!-- ******************** -->
  <!-- Summit XLS arguments -->
  <!-- ******************** -->
  <!-- ***************** -->
  <!-- Imported elements -->
  <!-- ***************** -->
  <!-- ********* -->
  <!-- Arguments -->
  <!-- ********* -->
  <!-- ***************** -->
  <!-- Imported elements -->
  <!-- ***************** -->
  <gazebo reference="base_footprint">
    <material>Gazebo/Green</material>
  </gazebo>
  <!-- in kg-->
  <!-- in kg-->
  <!-- Import holder for the boxes -->
  <!-- <xacro:include filename="$(find rbkairos_description)/urdf/box/holder.urdf.xacro" /> -->
  <!-- source en.wikipedia.org/wiki/List_of_moments_of_inertia-->
  <!-- This file unifies all sensors that can be used on simulation, defined as xacro:macros -->
  <!-- Includes -->
  <!-- Arguments set on rbkairos_state.launch -->
  <!-- Arm parameters -->
  <!-- <xacro:property name="arm_position_x" value="0.15887"/>
    <xacro:property name="arm_position_y" value="0"/>
    <xacro:property name="arm_position_z" value="0.56162"/>
    <xacro:property name="arm_orientation_r" value="0"/>
    <xacro:property name="arm_orientation_p" value="0"/>
    <xacro:property name="arm_orientation_y" value="0"/>	   -->
  <!-- <xacro:arg name="prefix" default="robot_"/> -->
  <!-- <xacro:arg name="ros_planar_move_plugin" default="false"/> -->
  <!-- <xacro:property name="arm_position_x" value="0.15887"/>
    <xacro:property name="arm_position_y" value="0"/>
    <xacro:property name="arm_position_z" value="0.56162"/>
    <xacro:property name="arm_orientation_r" value="0"/>
    <xacro:property name="arm_orientation_p" value="0"/>
    <xacro:property name="arm_orientation_y" value="0"/> -->
  <!--
  Author: Kelsey Hawkins
  Contributers: Jimmy Da Silva, Ajit Krisshna N L, Muhammad Asif Rana
  Modified by: Mattia Leonori
-->
  <!-- ****** -->
  <!-- Models -->
  <!-- ****** -->
  <!-- *************** -->
  <!-- Robots Elements -->
  <!-- *************** -->
  <!-- Here we create the robot elements using the xacro:macros imported at the beggining of this file -->
  <link name="rb_kairos_base_footprint">
    <visual>
      <origin rpy="0 0 0" xyz="0 0 0"/>
      <geometry>
        <box size="0.001 0.001 0.001"/>
      </geometry>
    </visual>
  </link>
  <joint name="rb_kairos_base_footprint_joint" type="fixed">
    <origin rpy="0 0 0" xyz="0 0 0.127"/>
    <!-- ${wheel_radius} property must be defined inside wheel description -->
    <parent link="rb_kairos_base_footprint"/>
    <child link="rb_kairos_base_link"/>
  </joint>
  <!-- BASE_LINK -->
  <link name="rb_kairos_base_link">
    <inertial>
      <mass value="125.0"/>
      <origin xyz="0 0 0"/>
      <inertia ixx="1.391" ixy="0.004" ixz="0.0" iyy="6.853" iyz="0.0" izz="6.125"/>
    </inertial>
    <visual>
      <origin rpy="0 0 0" xyz="0 0 0"/>
      <geometry>
        <mesh filename="package://hrii_robotnik_description/meshes/bases/xls/summit_xlsk_oem.stl"/>
      </geometry>
      <material name="black">
        <color rgba="0.0 0.0 0.0 1"/>
      </material>
    </visual>
    <collision>
      <origin rpy="0 0 0 " xyz="0 0 0"/>
      <geometry>
        <mesh filename="package://hrii_robotnik_description/meshes/bases/xls/summit_xlsk_oem.stl"/>
      </geometry>
    </collision>
  </link>
  <gazebo reference="rb_kairos_base_link">
    <material>Gazebo/Black</material>
  </gazebo>
  <!-- CHAPAS INOX TAPAS -->
  <link name="rb_kairos_base_chapa">
    <visual>
      <origin rpy="0 0 0" xyz="0 0 0"/>
      <geometry>
        <mesh filename="package://hrii_robotnik_description/meshes/bases/xls/summit_xls_chapas_inox_tapas.stl"/>
      </geometry>
      <material name="darkgrey">
        <color rgba="0.5 0.5 0.5 1"/>
      </material>
    </visual>
  </link>
  <joint name="rb_kairos_base_tapa_joint" type="fixed">
    <origin rpy="0 0 0" xyz="0.0 0 0.38062"/>
    <parent link="rb_kairos_base_link"/>
    <child link="rb_kairos_base_chapa"/>
  </joint>
  <!-- LOGO ROBOTNIK IZQUIERDO -->
  <link name="rb_kairos_base_logo_left">
    <visual>
      <origin rpy="0 0 0" xyz="0 0 0"/>
      <geometry>
        <mesh filename="package://hrii_robotnik_description/meshes/bases/xls/robotnik_logo_chasis.stl"/>
      </geometry>
      <material name="darkgrey">
        <color rgba="0.5 0.5 0.5 1"/>
      </material>
    </visual>
  </link>
  <joint name="rb_kairos_base_logo_left_joint" type="fixed">
    <origin rpy="0 0 0" xyz="0.0 0.28931 0.29062"/>
    <parent link="rb_kairos_base_link"/>
    <child link="rb_kairos_base_logo_left"/>
  </joint>
  <!-- LOGO ROBOTNIK DERECHO -->
  <link name="rb_kairos_base_logo_right">
    <visual>
      <origin rpy="0 0 0" xyz="0 0 0"/>
      <geometry>
        <mesh filename="package://hrii_robotnik_description/meshes/bases/xls/robotnik_logo_chasis.stl"/>
      </geometry>
      <material name="darkgrey">
        <color rgba="0.5 0.5 0.5 1"/>
      </material>
    </visual>
  </link>
  <joint name="rb_kairos_base_logo_right_joint" type="fixed">
    <origin rpy="0 0 3.141592653589793" xyz="0.0 -0.28931 0.29062"/>
    <parent link="rb_kairos_base_link"/>
    <child link="rb_kairos_base_logo_right"/>
  </joint>
  <!-- LOGO ROBOTNIK FRONTAL -->
  <link name="rb_kairos_base_logo_front">
    <visual>
      <origin rpy="0 0 0" xyz="0 0 0"/>
      <geometry>
        <mesh filename="package://hrii_robotnik_description/meshes/bases/xls/robotnik_logo_chasis.stl"/>
      </geometry>
      <material name="darkgrey">
        <color rgba="0.5 0.5 0.5 1"/>
      </material>
    </visual>
  </link>
  <joint name="rb_kairos_base_logo_front_joint" type="fixed">
    <origin rpy="0 0 -1.5707963267948966" xyz="0.345 0.0 0.0"/>
    <parent link="rb_kairos_base_link"/>
    <child link="rb_kairos_base_logo_front"/>
  </joint>
  <!-- LOGO ROBOTNIK TRASERO -->
  <link name="rb_kairos_base_logo_rear">
    <visual>
      <origin rpy="0 0 0" xyz="0 0 0"/>
      <geometry>
        <mesh filename="package://hrii_robotnik_description/meshes/bases/xls/robotnik_logo_chasis.stl"/>
      </geometry>
      <material name="darkgrey">
        <color rgba="0.5 0.5 0.5 1"/>
      </material>
    </visual>
  </link>
  <joint name="rb_kairos_base_logo_rear_joint" type="fixed">
    <origin rpy="0 0 1.5707963267948966" xyz="-0.345 0.0 0.0"/>
    <parent link="rb_kairos_base_link"/>
    <child link="rb_kairos_base_logo_rear"/>
  </joint>
  <!-- DOCKING CONTACT -->
  <link name="rb_kairos_base_docking_contact">
    </link>
  <joint name="rb_kairos_base_docking_joint" type="fixed">
    <origin rpy="0 0 0" xyz="0.35 0 0.09"/>
    <parent link="rb_kairos_base_link"/>
    <child link="rb_kairos_base_docking_contact"/>
  </joint>
  <joint name="rb_kairos_front_right_wheel_joint" type="continuous">
    <parent link="rb_kairos_base_link"/>
    <child link="rb_kairos_front_right_wheel_link"/>
    <origin rpy="0 0 0" xyz="0.21528 -0.269 0.0"/>
    <axis rpy="0 0 0" xyz="0 1 0"/>
    <limit effort="100" velocity="100"/>
    <joint_properties damping="0.0" friction="0.0"/>
  </joint>
  <link name="rb_kairos_front_right_wheel_link">
    <visual>
      <origin rpy="0 0 0" xyz="0 0 0"/>
      <geometry>
        <mesh filename="package://hrii_robotnik_description/meshes/wheels/omni_wheel_2.dae"/>
      </geometry>
      <material name="darkgrey">
        <color rgba="0.2 0.2 0.2 1"/>
      </material>
    </visual>
    <collision>
      <origin rpy="1.570795 0 0" xyz="0 0 0"/>
      <geometry>
        <!-- <sphere radius="${omni_wheel_radius}" /> -->
        <!--
          <xacro:if value="${reflect}">
              <mesh filename="package://hrii_robotnik_description/meshes/wheels/omni_wheel_1.dae" />
          </xacro:if>
          <xacro:unless value="${reflect}">
              <mesh filename="package://hrii_robotnik_description/meshes/wheels/omni_wheel_2.dae" />
					</xacro:unless>
-->
        <cylinder length="0.087" radius="0.127"/>
      </geometry>
    </collision>
    <inertial>
      <mass value="6.5"/>
      <origin xyz="0 0 0"/>
      <inertia ixx="0.0303095" ixy="0" ixz="0" iyy="0.05241925" iyz="0" izz="0.0303095"/>
    </inertial>
  </link>
  <!-- Transmission is important to link the joints and the controller (see summit_xl_control/config/summit_xl_control.yaml)-->
  <transmission name="rb_kairos_front_right_wheel_joint_trans">
    <type>transmission_interface/SimpleTransmission</type>
    <joint name="rb_kairos_front_right_wheel_joint">
      <hardwareInterface>hardware_interface/VelocityJointInterface</hardwareInterface>
    </joint>
    <actuator name="rb_kairos_front_right_wheel_joint_motor">
      <mechanicalReduction>1</mechanicalReduction>
    </actuator>
  </transmission>
  <gazebo reference="rb_kairos_front_right_wheel_link">
    <mu1 value="0.2"/>
    <mu2 value="0.2"/>
    <minDepth value="0.001"/>
  </gazebo>
  <joint name="rb_kairos_front_left_wheel_joint" type="continuous">
    <parent link="rb_kairos_base_link"/>
    <child link="rb_kairos_front_left_wheel_link"/>
    <origin rpy="0 0 0" xyz="0.21528 0.269 0.0"/>
    <axis rpy="0 0 0" xyz="0 1 0"/>
    <limit effort="100" velocity="100"/>
    <joint_properties damping="0.0" friction="0.0"/>
  </joint>
  <link name="rb_kairos_front_left_wheel_link">
    <visual>
      <origin rpy="0 0 0" xyz="0 0 0"/>
      <geometry>
        <mesh filename="package://hrii_robotnik_description/meshes/wheels/omni_wheel_1.dae"/>
      </geometry>
      <material name="darkgrey">
        <color rgba="0.2 0.2 0.2 1"/>
      </material>
    </visual>
    <collision>
      <origin rpy="1.570795 0 0" xyz="0 0 0"/>
      <geometry>
        <!-- <sphere radius="${omni_wheel_radius}" /> -->
        <!--
          <xacro:if value="${reflect}">
              <mesh filename="package://hrii_robotnik_description/meshes/wheels/omni_wheel_1.dae" />
          </xacro:if>
          <xacro:unless value="${reflect}">
              <mesh filename="package://hrii_robotnik_description/meshes/wheels/omni_wheel_2.dae" />
					</xacro:unless>
-->
        <cylinder length="0.087" radius="0.127"/>
      </geometry>
    </collision>
    <inertial>
      <mass value="6.5"/>
      <origin xyz="0 0 0"/>
      <inertia ixx="0.0303095" ixy="0" ixz="0" iyy="0.05241925" iyz="0" izz="0.0303095"/>
    </inertial>
  </link>
  <!-- Transmission is important to link the joints and the controller (see summit_xl_control/config/summit_xl_control.yaml)-->
  <transmission name="rb_kairos_front_left_wheel_joint_trans">
    <type>transmission_interface/SimpleTransmission</type>
    <joint name="rb_kairos_front_left_wheel_joint">
      <hardwareInterface>hardware_interface/VelocityJointInterface</hardwareInterface>
    </joint>
    <actuator name="rb_kairos_front_left_wheel_joint_motor">
      <mechanicalReduction>1</mechanicalReduction>
    </actuator>
  </transmission>
  <gazebo reference="rb_kairos_front_left_wheel_link">
    <mu1 value="0.2"/>
    <mu2 value="0.2"/>
    <minDepth value="0.001"/>
  </gazebo>
  <joint name="rb_kairos_back_left_wheel_joint" type="continuous">
    <parent link="rb_kairos_base_link"/>
    <child link="rb_kairos_back_left_wheel_link"/>
    <origin rpy="0 0 0" xyz="-0.21528 0.269 0.0"/>
    <axis rpy="0 0 0" xyz="0 1 0"/>
    <limit effort="100" velocity="100"/>
    <joint_properties damping="0.0" friction="0.0"/>
  </joint>
  <link name="rb_kairos_back_left_wheel_link">
    <visual>
      <origin rpy="0 0 0" xyz="0 0 0"/>
      <geometry>
        <mesh filename="package://hrii_robotnik_description/meshes/wheels/omni_wheel_1.dae"/>
      </geometry>
      <material name="darkgrey">
        <color rgba="0.2 0.2 0.2 1"/>
      </material>
    </visual>
    <collision>
      <origin rpy="1.570795 0 0" xyz="0 0 0"/>
      <geometry>
        <!-- <sphere radius="${omni_wheel_radius}" /> -->
        <!--
          <xacro:if value="${reflect}">
              <mesh filename="package://hrii_robotnik_description/meshes/wheels/omni_wheel_1.dae" />
          </xacro:if>
          <xacro:unless value="${reflect}">
              <mesh filename="package://hrii_robotnik_description/meshes/wheels/omni_wheel_2.dae" />
					</xacro:unless>
-->
        <cylinder length="0.087" radius="0.127"/>
      </geometry>
    </collision>
    <inertial>
      <mass value="6.5"/>
      <origin xyz="0 0 0"/>
      <inertia ixx="0.0303095" ixy="0" ixz="0" iyy="0.05241925" iyz="0" izz="0.0303095"/>
    </inertial>
  </link>
  <!-- Transmission is important to link the joints and the controller (see summit_xl_control/config/summit_xl_control.yaml)-->
  <transmission name="rb_kairos_back_left_wheel_joint_trans">
    <type>transmission_interface/SimpleTransmission</type>
    <joint name="rb_kairos_back_left_wheel_joint">
      <hardwareInterface>hardware_interface/VelocityJointInterface</hardwareInterface>
    </joint>
    <actuator name="rb_kairos_back_left_wheel_joint_motor">
      <mechanicalReduction>1</mechanicalReduction>
    </actuator>
  </transmission>
  <gazebo reference="rb_kairos_back_left_wheel_link">
    <mu1 value="0.2"/>
    <mu2 value="0.2"/>
    <minDepth value="0.001"/>
  </gazebo>
  <joint name="rb_kairos_back_right_wheel_joint" type="continuous">
    <parent link="rb_kairos_base_link"/>
    <child link="rb_kairos_back_right_wheel_link"/>
    <origin rpy="0 0 0" xyz="-0.21528 -0.269 0.0"/>
    <axis rpy="0 0 0" xyz="0 1 0"/>
    <limit effort="100" velocity="100"/>
    <joint_properties damping="0.0" friction="0.0"/>
  </joint>
  <link name="rb_kairos_back_right_wheel_link">
    <visual>
      <origin rpy="0 0 0" xyz="0 0 0"/>
      <geometry>
        <mesh filename="package://hrii_robotnik_description/meshes/wheels/omni_wheel_2.dae"/>
      </geometry>
      <material name="darkgrey">
        <color rgba="0.2 0.2 0.2 1"/>
      </material>
    </visual>
    <collision>
      <origin rpy="1.570795 0 0" xyz="0 0 0"/>
      <geometry>
        <!-- <sphere radius="${omni_wheel_radius}" /> -->
        <!--
          <xacro:if value="${reflect}">
              <mesh filename="package://hrii_robotnik_description/meshes/wheels/omni_wheel_1.dae" />
          </xacro:if>
          <xacro:unless value="${reflect}">
              <mesh filename="package://hrii_robotnik_description/meshes/wheels/omni_wheel_2.dae" />
					</xacro:unless>
-->
        <cylinder length="0.087" radius="0.127"/>
      </geometry>
    </collision>
    <inertial>
      <mass value="6.5"/>
      <origin xyz="0 0 0"/>
      <inertia ixx="0.0303095" ixy="0" ixz="0" iyy="0.05241925" iyz="0" izz="0.0303095"/>
    </inertial>
  </link>
  <!-- Transmission is important to link the joints and the controller (see summit_xl_control/config/summit_xl_control.yaml)-->
  <transmission name="rb_kairos_back_right_wheel_joint_trans">
    <type>transmission_interface/SimpleTransmission</type>
    <joint name="rb_kairos_back_right_wheel_joint">
      <hardwareInterface>hardware_interface/VelocityJointInterface</hardwareInterface>
    </joint>
    <actuator name="rb_kairos_back_right_wheel_joint_motor">
      <mechanicalReduction>1</mechanicalReduction>
    </actuator>
  </transmission>
  <gazebo reference="rb_kairos_back_right_wheel_link">
    <mu1 value="0.2"/>
    <mu2 value="0.2"/>
    <minDepth value="0.001"/>
  </gazebo>
  <joint name="rb_kairos_imu_joint" type="fixed">
    <axis xyz="1 0 0"/>
    <!--origin xyz="0 0 0.2825"/-->
    <origin rpy="0 0 0" xyz="0.127 -0.129 0.212"/>
    <parent link="rb_kairos_base_link"/>
    <child link="rb_kairos_imu_link"/>
  </joint>
  <link name="rb_kairos_imu_link">
    <inertial>
      <origin rpy="0 0 0" xyz="0.0 0 0.01"/>
      <mass value="0.05"/>
      <inertia ixx="3.3333333333333337e-06" ixy="0" ixz="0" iyy="3.3333333333333337e-06" iyz="0" izz="3.3333333333333337e-06"/>
    </inertial>
    <visual>
      <origin rpy="0 0 0" xyz="0 0 0"/>
      <geometry>
        <box size="0.001 0.001 0.001"/>
      </geometry>
    </visual>
    <collision>
      <origin rpy="0 0 0" xyz="0 0 0"/>
      <geometry>
        <box size=".001 .001 .001"/>
      </geometry>
    </collision>
  </link>
  <gazebo>
    <plugin filename="libhector_gazebo_ros_imu.so" name="rb_kairos_imu_controller">
      <alwaysOn>true</alwaysOn>
      <topicName>imu/data</topicName>
      <serviceName>rb_kairos_imuimu/service</serviceName>
      <bodyName>rb_kairos_imu_link</bodyName>
      <frameId>rb_kairos_imu_link</frameId>
      <updateRate>50.0</updateRate>
      <gaussianNoise>0.00</gaussianNoise>
      <yawOffset>0.0</yawOffset>
      <yawDrift>0.0</yawDrift>
      <yawGaussianNoise>0.0</yawGaussianNoise>
      <!-- angular velocities parameters -->
      <rateOffset>0.0 0.0 0.0</rateOffset>
      <rateDrift>0.0 0.0 0.0</rateDrift>
      <rateGaussianNoise>0.0 0.0 0.0</rateGaussianNoise>
      <!-- linear accelerations parameters -->
      <accelOffset>0.0 0.0 0.0</accelOffset>
      <accelDrift>0.0 0.0 0.0</accelDrift>
      <accelGaussianNoise>0.0 0.0 0.0</accelGaussianNoise>
    </plugin>
  </gazebo>
  <joint name="rb_kairos_front_laser_base_joint" type="fixed">
    <origin rpy="0 3.14159 2.3561924999999997" xyz="0.28783 -0.2224 0.22365"/>
    <parent link="rb_kairos_base_link"/>
    <child link="rb_kairos_front_laser_base_link"/>
  </joint>
  <link name="rb_kairos_front_laser_base_link">
    <collision>
      <origin rpy="0 0 0" xyz="0 0 0.0"/>
      <geometry>
        <box size="0.010 0.010 0.010"/>
      </geometry>
    </collision>
    <visual>
      <origin rpy="0 0 0" xyz="0 0 0.0"/>
      <geometry>
        <mesh filename="package://robotnik_sensors/meshes/hokuyo_ust_10lx.dae"/>
      </geometry>
    </visual>
    <inertial>
      <origin rpy="0 0 0" xyz="0.0 0 0.035"/>
      <mass value="0.130"/>
      <inertia ixx="8.016666666666669e-05" ixy="0" ixz="0" iyy="8.016666666666669e-05" iyz="0" izz="5.4166666666666685e-05"/>
    </inertial>
  </link>
  <joint name="rb_kairos_front_laser_joint" type="fixed">
    <origin rpy="0 0 0" xyz="0 0 0.0474"/>
    <parent link="rb_kairos_front_laser_base_link"/>
    <child link="rb_kairos_front_laser_link"/>
  </joint>
  <link name="rb_kairos_front_laser_link">
    </link>
  <gazebo reference="rb_kairos_front_laser_link">
    <sensor name="rb_kairos_front_laser_sensor" type="gpu_ray">
      <pose>0 0 0 0 0 0</pose>
      <visualize>false</visualize>
      <update_rate>40</update_rate>
      <ray>
        <scan>
          <horizontal>
            <samples>1081</samples>
            <resolution>1</resolution>
            <min_angle>-2.3562</min_angle>
            <max_angle>2.3562</max_angle>
          </horizontal>
        </scan>
        <range>
          <min>0.06</min>
          <max>10.0</max>
          <!-- resolution>0.004363323</resolution -->
          <resolution>0.004359297</resolution>
          <!-- resolution>0.001</resolution -->
        </range>
        <noise>
          <type>gaussian</type>
          <mean>0.0</mean>
          <stddev>0.01</stddev>
        </noise>
      </ray>
      <plugin filename="libgazebo_ros_gpu_laser.so" name="rb_kairos_front_laser_controller">
        <topicName>front_laser/scan</topicName>
        <frameName>/rb_kairos_front_laser_link</frameName>
      </plugin>
    </sensor>
  </gazebo>
  <joint name="rb_kairos_rear_laser_base_joint" type="fixed">
    <origin rpy="0 3.14159 -0.7853975" xyz="-0.28783 0.2224 0.22365"/>
    <parent link="rb_kairos_base_link"/>
    <child link="rb_kairos_rear_laser_base_link"/>
  </joint>
  <link name="rb_kairos_rear_laser_base_link">
    <collision>
      <origin rpy="0 0 0" xyz="0 0 0.0"/>
      <geometry>
        <box size="0.010 0.010 0.010"/>
      </geometry>
    </collision>
    <visual>
      <origin rpy="0 0 0" xyz="0 0 0.0"/>
      <geometry>
        <mesh filename="package://robotnik_sensors/meshes/hokuyo_ust_10lx.dae"/>
      </geometry>
    </visual>
    <inertial>
      <origin rpy="0 0 0" xyz="0.0 0 0.035"/>
      <mass value="0.130"/>
      <inertia ixx="8.016666666666669e-05" ixy="0" ixz="0" iyy="8.016666666666669e-05" iyz="0" izz="5.4166666666666685e-05"/>
    </inertial>
  </link>
  <joint name="rb_kairos_rear_laser_joint" type="fixed">
    <origin rpy="0 0 0" xyz="0 0 0.0474"/>
    <parent link="rb_kairos_rear_laser_base_link"/>
    <child link="rb_kairos_rear_laser_link"/>
  </joint>
  <link name="rb_kairos_rear_laser_link">
    </link>
  <gazebo reference="rb_kairos_rear_laser_link">
    <sensor name="rb_kairos_rear_laser_sensor" type="gpu_ray">
      <pose>0 0 0 0 0 0</pose>
      <visualize>false</visualize>
      <update_rate>40</update_rate>
      <ray>
        <scan>
          <horizontal>
            <samples>1081</samples>
            <resolution>1</resolution>
            <min_angle>-2.3562</min_angle>
            <max_angle>2.3562</max_angle>
          </horizontal>
        </scan>
        <range>
          <min>0.06</min>
          <max>10.0</max>
          <!-- resolution>0.004363323</resolution -->
          <resolution>0.004359297</resolution>
          <!-- resolution>0.001</resolution -->
        </range>
        <noise>
          <type>gaussian</type>
          <mean>0.0</mean>
          <stddev>0.01</stddev>
        </noise>
      </ray>
      <plugin filename="libgazebo_ros_gpu_laser.so" name="rb_kairos_rear_laser_controller">
        <topicName>rear_laser/scan</topicName>
        <frameName>/rb_kairos_rear_laser_link</frameName>
      </plugin>
    </sensor>
  </gazebo>
  <joint name="rb_kairos_front_rgbd_camera_joint" type="fixed">
    <origin rpy="0 0 0" xyz="0.3585 0.0 0.28062"/>
    <parent link="rb_kairos_base_link"/>
    <child link="rb_kairos_front_rgbd_camera_link"/>
  </joint>
  <link name="rb_kairos_front_rgbd_camera_link">
    <!--visual>
      <origin rpy="0 0 0" xyz="0 0 0"/>
      <geometry>
        <mesh filename="package://robotnik_sensors/meshes/orbbec_astra.dae"/>
      </geometry>
    </visual>
    <collision>
      <geometry>
        <mesh filename="package://robotnik_sensors/meshes/orbbec_astra.dae"/>
      </geometry>
    </collision-->
    <inertial>
      <mass value="0.001"/>
      <origin xyz="0.0 0.0 0.0"/>
      <inertia ixx="2.3437500000000006e-06" ixy="0" ixz="0" iyy="2.0833333333333336e-07" iyz="0" izz="2.4020833333333336e-06"/>
    </inertial>
  </link>
  <joint name="rb_kairos_front_rgbd_camera_rgb_joint" type="fixed">
    <origin rpy="0.0 0.0 0.0" xyz="0.0 0.0125 0.0150"/>
    <parent link="rb_kairos_front_rgbd_camera_link"/>
    <child link="rb_kairos_front_rgbd_camera_rgb_frame"/>
  </joint>
  <link name="rb_kairos_front_rgbd_camera_rgb_frame">
    <inertial>
      <mass value="0.297"/>
      <origin xyz="-0.02 -0.0125 0.0"/>
      <inertia ixx="0.0006960937500000001" ixy="0" ixz="0" iyy="6.1875e-05" iyz="0" izz="0.00071341875"/>
    </inertial>
  </link>
  <joint name="rb_kairos_front_rgbd_camera_rgb_optical_joint" type="fixed">
    <origin rpy="-1.5707963267948966 0 -1.5707963267948966" xyz="0.0 0.0 0.0"/>
    <parent link="rb_kairos_front_rgbd_camera_rgb_frame"/>
    <child link="rb_kairos_front_rgbd_camera_rgb_optical_frame"/>
  </joint>
  <link name="rb_kairos_front_rgbd_camera_rgb_optical_frame">
    <inertial>
      <mass value="0.001"/>
      <!--origin xyz="0 0 0" rpy="${M_PI/2} 0 ${M_PI/2}"/-->
      <origin rpy="0 0 0" xyz="0 0 0"/>
      <inertia ixx="2.3437500000000006e-06" ixy="0" ixz="0" iyy="2.0833333333333336e-07" iyz="0" izz="2.4020833333333336e-06"/>
    </inertial>
  </link>
  <joint name="rb_kairos_front_rgbd_camera_depth_joint" type="fixed">
    <origin rpy="0 0 0" xyz="0.0 0.0375 0.0150"/>
    <parent link="rb_kairos_front_rgbd_camera_link"/>
    <child link="rb_kairos_front_rgbd_camera_depth_frame"/>
  </joint>
  <link name="rb_kairos_front_rgbd_camera_depth_frame">
    <inertial>
      <mass value="0.001"/>
      <origin xyz="0 0 0"/>
      <inertia ixx="2.3437500000000006e-06" ixy="0" ixz="0" iyy="2.0833333333333336e-07" iyz="0" izz="2.4020833333333336e-06"/>
    </inertial>
  </link>
  <joint name="rb_kairos_front_rgbd_camera_depth_optical_joint" type="fixed">
    <origin rpy="-1.5707963267948966 0 -1.5707963267948966" xyz="0 0 0"/>
    <parent link="rb_kairos_front_rgbd_camera_depth_frame"/>
    <child link="rb_kairos_front_rgbd_camera_depth_optical_frame"/>
  </joint>
  <link name="rb_kairos_front_rgbd_camera_depth_optical_frame">
    <inertial>
      <mass value="0.001"/>
      <origin xyz="0 0 0"/>
      <inertia ixx="2.3437500000000006e-06" ixy="0" ixz="0" iyy="2.0833333333333336e-07" iyz="0" izz="2.4020833333333336e-06"/>
    </inertial>
  </link>
  <!-- RGBD sensor for simulation, same as Kinect -->
  <!-- <sensor_orbbec_astra_gazebo/> -->
  <gazebo reference="rb_kairos_front_rgbd_camera_link">
    <sensor name="rb_kairos_front_rgbd_camera_depth_sensor" type="depth">
      <always_on>true</always_on>
      <update_rate>20.0</update_rate>
      <camera>
        <horizontal_fov>1.0471975511965976</horizontal_fov>
        <image>
          <format>R8G8B8</format>
          <width>640</width>
          <height>480</height>
        </image>
        <clip>
          <near>0.05</near>
          <far>3.5</far>
        </clip>
      </camera>
      <plugin filename="libgazebo_ros_openni_kinect.so" name="rb_kairos_front_rgbd_camera_controller">
        <cameraName>front_rgbd_camera</cameraName>
        <alwaysOn>true</alwaysOn>
        <updateRate>10</updateRate>
        <imageTopicName>rgb/image_raw</imageTopicName>
        <depthImageTopicName>depth/image_raw</depthImageTopicName>
        <pointCloudTopicName>depth/points</pointCloudTopicName>
        <cameraInfoTopicName>rgb/camera_info</cameraInfoTopicName>
        <depthImageCameraInfoTopicName>depth/camera_info</depthImageCameraInfoTopicName>
        <frameName>/rb_kairos_front_rgbd_camera_depth_optical_frame</frameName>
        <baseline>0.1</baseline>
        <distortion_k1>0.0</distortion_k1>
        <distortion_k2>0.0</distortion_k2>
        <distortion_k3>0.0</distortion_k3>
        <distortion_t1>0.0</distortion_t1>
        <distortion_t2>0.0</distortion_t2>
        <pointCloudCutoff>0.4</pointCloudCutoff>
      </plugin>
    </sensor>
  </gazebo>
  <!--xacro:sensor_zed prefix="${prefix}front_rgbd_camera" parent="${prefix}base_link" prefix_topic="front_rgbd_camera">
  			<origin xyz="${front_rgbd_camera_offset_x} ${front_rgbd_camera_offset_y} ${front_rgbd_camera_offset_z}" rpy="0 0 0"/>
  		</xacro:sensor_zed-->
  <!-- HOLDERS -->
  <!-- <xacro:holder prefix="${prefix}center_" parent="${prefix}base_link">
  			<origin xyz="${center_holder_offset_x} ${center_holder_offset_y} ${center_holder_offset_z}" rpy="0 0 0"/>
  		</xacro:holder>

  		<xacro:holder prefix="${prefix}left_" parent="${prefix}base_link">
  			<origin xyz="${left_holder_offset_x} ${left_holder_offset_y} ${left_holder_offset_z}" rpy="0 0 0"/>
  		</xacro:holder>

  		<xacro:holder prefix="${prefix}right_" parent="${prefix}base_link">
  			<origin xyz="${right_holder_offset_x} ${right_holder_offset_y} ${right_holder_offset_z}" rpy="0 0 0"/>
  		</xacro:holder>  -->
  <!-- Intel Realsense support-->
  <!--xacro:realsense2vgc10_support prefix="$(arg prefix)wrist_rgbd_support" parent="$(arg prefix)arm_tool0">
            <origin xyz="0.0 0.0 0.0" rpy="0 0 0.0"/>
  		</xacro:realsense2vgc10_support-->
  <!-- Intel Realsense -->
  <!--<xacro:sensor_intel_d435 prefix="$(arg prefix)wrist_rgbd" parent="$(arg prefix)arm_tool0" prefix_topic="wrist_rgbd">-->
  <!--<origin xyz="0.07 0.0 0.065" rpy="${pi} ${-pi/2} 0"/>-->
  <!--</xacro:sensor_intel_d435>-->
  <!-- ******* -->
  <!-- Plugins -->
  <!-- ******* -->
  <!-- <xacro:if value="$(arg ros_planar_move_plugin)">
            <xacro:omni_steering prefix="${prefix}" publish_tf="false"/>
        </xacro:if>

        <xacro:if value="$(arg ros_force_based_move)">
            <xacro:ros_force_based_move prefix="${prefix}" publish_tf="false"/>

            <xacro:ros_gazebo_odometry  odom_topic_name="robotnik_base_control/odom" 
                                        odom_frame_name="${prefix}odom"
                                        body_link_name="${prefix}base_footprint"/>
        </xacro:if>

        <xacro:if value="$(arg gazebo_ros_control)">
            <xacro:ros_control/>
        </xacro:if> -->
  <!-- measured from model -->
  <!-- manually measured -->
  <link name="rb_kairos_ur16e_base_link">
    <visual>
      <geometry>
        <mesh filename="package://hrii_universal_robots_description/meshes/ur5e/visual/base.dae"/>
      </geometry>
      <material name="LightGrey">
        <color rgba="0.7 0.7 0.7 1.0"/>
      </material>
    </visual>
    <!--collision>
      <geometry>
        <mesh filename="package://hrii_universal_robots_description/meshes/ur5e/collision/base.stl"/>
      </geometry>
    </collision-->
    <inertial>
      <mass value="4.0"/>
      <origin rpy="0 0 0" xyz="0.0 0.0 0.0"/>
      <inertia ixx="0.00443333156" ixy="0.0" ixz="0.0" iyy="0.00443333156" iyz="0.0" izz="0.0072"/>
    </inertial>
  </link>
  <joint name="rb_kairos_ur16e_shoulder_pan_joint" type="continuous">
    <parent link="rb_kairos_ur16e_base_link"/>
    <child link="rb_kairos_ur16e_shoulder_link"/>
    <origin rpy="0.0 0.0 3.14159" xyz="0.0 0.0 0.1625"/>
    <axis xyz="0 0 1"/>
    <limit effort="150.0" lower="-6.28318" upper="6.28318" velocity="3.15"/>
    <dynamics damping="0.0" friction="0.0"/>
    <!-- <dynamics damping="${joint_damping}" friction="${joint_friction}"/> -->
  </joint>
  <link name="rb_kairos_ur16e_shoulder_link">
    <visual>
      <origin rpy="0 0 3.14159" xyz="0 0 0"/>
      <geometry>
        <mesh filename="package://hrii_universal_robots_description/meshes/ur5e/visual/shoulder.dae"/>
      </geometry>
      <material name="LightGrey">
        <color rgba="0.7 0.7 0.7 1.0"/>
      </material>
    </visual>
    <collision>
      <origin rpy="0 0 3.14159" xyz="0 0 0"/>
      <geometry>
        <mesh filename="package://hrii_universal_robots_description/meshes/ur5e/collision/shoulder.stl"/>
      </geometry>
    </collision>
    <inertial>
      <mass value="3.7"/>
      <origin rpy="0 0 0" xyz="0.0 0.0 0.0"/>
      <inertia ixx="0.010267495893" ixy="0.0" ixz="0.0" iyy="0.010267495893" iyz="0.0" izz="0.00666"/>
    </inertial>
  </link>
  <joint name="rb_kairos_ur16e_shoulder_lift_joint" type="continuous">
    <parent link="rb_kairos_ur16e_shoulder_link"/>
    <child link="rb_kairos_ur16e_upper_arm_link"/>
    <origin rpy="1.570795 0.0 0.0" xyz="0.0 0.0 0.0"/>
    <axis xyz="0 0 1"/>
    <limit effort="150.0" lower="-6.28318" upper="6.28318" velocity="3.15"/>
    <dynamics damping="0.0" friction="0.0"/>
    <!-- <dynamics damping="${joint_damping}" friction="${joint_friction}"/> -->
  </joint>
  <link name="rb_kairos_ur16e_upper_arm_link">
    <visual>
      <origin rpy="1.570795 0 -1.570795" xyz="0 0 0.138"/>
      <geometry>
        <mesh filename="package://hrii_universal_robots_description/meshes/ur5e/visual/upperarm.dae"/>
      </geometry>
      <material name="LightGrey">
        <color rgba="0.7 0.7 0.7 1.0"/>
      </material>
    </visual>
    <collision>
      <origin rpy="1.570795 0 -1.570795" xyz="0 0 0.138"/>
      <geometry>
        <mesh filename="package://hrii_universal_robots_description/meshes/ur5e/collision/upperarm.stl"/>
      </geometry>
    </collision>
    <inertial>
      <mass value="8.393"/>
      <origin rpy="0 0 0" xyz="0.2125 0.0 0.138"/>
      <inertia ixx="0.13813473641275" ixy="0.0" ixz="0.0" iyy="0.13813473641275" iyz="0.0" izz="0.0236053125"/>
    </inertial>
  </link>
  <joint name="rb_kairos_ur16e_elbow_joint" type="continuous">
    <parent link="rb_kairos_ur16e_upper_arm_link"/>
    <child link="rb_kairos_ur16e_forearm_link"/>
    <origin rpy="0.0 0.0 0.0" xyz="-0.425 0.0 0.0"/>
    <axis xyz="0 0 1"/>
    <limit effort="150.0" lower="-6.28318" upper="6.28318" velocity="3.15"/>
    <dynamics damping="0.0" friction="0.0"/>
    <!-- <dynamics damping="${joint_damping}" friction="${joint_friction}"/> -->
  </joint>
  <link name="rb_kairos_ur16e_forearm_link">
    <visual>
      <origin rpy="1.570795 0 -1.570795" xyz="0 0 0.007"/>
      <geometry>
        <mesh filename="package://hrii_universal_robots_description/meshes/ur5e/visual/forearm.dae"/>
      </geometry>
      <material name="LightGrey">
        <color rgba="0.7 0.7 0.7 1.0"/>
      </material>
    </visual>
    <collision>
      <origin rpy="1.570795 0 -1.570795" xyz="0 0 0.007"/>
      <geometry>
        <mesh filename="package://hrii_universal_robots_description/meshes/ur5e/collision/forearm.stl"/>
      </geometry>
    </collision>
    <inertial>
      <mass value="2.275"/>
      <origin rpy="0 0 0" xyz="0.1961 0.0 0.007"/>
      <inertia ixx="0.0323610733888988" ixy="0.0" ixz="0.0" iyy="0.0323610733888988" iyz="0.0" izz="0.0063984375"/>
    </inertial>
  </link>
  <joint name="rb_kairos_ur16e_wrist_1_joint" type="continuous">
    <parent link="rb_kairos_ur16e_forearm_link"/>
    <child link="rb_kairos_ur16e_wrist_1_link"/>
    <origin rpy="0.0 0.0 0.0" xyz="-0.3922 0.0 0.1333"/>
    <axis xyz="0 0 1"/>
    <limit effort="28.0" lower="-6.28318" upper="6.28318" velocity="6.28"/>
    <dynamics damping="0.0" friction="0.0"/>
    <!-- <dynamics damping="${joint_damping}" friction="${joint_friction}"/> -->
  </joint>
  <link name="rb_kairos_ur16e_wrist_1_link">
    <visual>
      <origin rpy="1.5707963267948966 0 0" xyz="0 0 -0.127"/>
      <geometry>
        <mesh filename="package://hrii_universal_robots_description/meshes/ur5e/visual/wrist1.dae"/>
      </geometry>
      <material name="LightGrey">
        <color rgba="0.7 0.7 0.7 1.0"/>
      </material>
    </visual>
    <collision>
      <origin rpy="1.5707963267948966 0 0" xyz="0 0 -0.127"/>
      <geometry>
        <mesh filename="package://hrii_universal_robots_description/meshes/ur5e/collision/wrist1.stl"/>
      </geometry>
    </collision>
    <inertial>
      <mass value="1.219"/>
      <origin rpy="0 0 0" xyz="0.0 0.0 0.0"/>
      <inertia ixx="0.002723965136246843" ixy="0.0" ixz="0.0" iyy="0.002723965136246843" iyz="0.0" izz="0.0034284375"/>
    </inertial>
  </link>
  <joint name="rb_kairos_ur16e_wrist_2_joint" type="continuous">
    <parent link="rb_kairos_ur16e_wrist_1_link"/>
    <child link="rb_kairos_ur16e_wrist_2_link"/>
    <origin rpy="1.570795 0.0 0.0" xyz="0.0 -0.0997 0.0"/>
    <axis xyz="0 0 1"/>
    <limit effort="28.0" lower="-6.28318" upper="6.28318" velocity="3.2"/>
    <dynamics damping="0.0" friction="0.0"/>
    <!-- <dynamics damping="${joint_damping}" friction="${joint_friction}"/> -->
  </joint>
  <link name="rb_kairos_ur16e_wrist_2_link">
    <visual>
      <origin rpy="0 0 0" xyz="0 0 -0.0997"/>
      <geometry>
        <mesh filename="package://hrii_universal_robots_description/meshes/ur5e/visual/wrist2.dae"/>
      </geometry>
      <material name="LightGrey">
        <color rgba="0.7 0.7 0.7 1.0"/>
      </material>
    </visual>
    <collision>
      <origin rpy="0 0 0" xyz="0 0 -0.0997"/>
      <geometry>
        <mesh filename="package://hrii_universal_robots_description/meshes/ur5e/collision/wrist2.stl"/>
      </geometry>
    </collision>
    <inertial>
      <mass value="1.219"/>
      <origin rpy="0 0 0" xyz="0.0 0.0 0.0"/>
      <inertia ixx="0.002721940581223332" ixy="0.0" ixz="0.0" iyy="0.002721940581223332" iyz="0.0" izz="0.0034284375"/>
    </inertial>
  </link>
  <joint name="rb_kairos_ur16e_wrist_3_joint" type="continuous">
    <parent link="rb_kairos_ur16e_wrist_2_link"/>
    <child link="rb_kairos_ur16e_wrist_3_link"/>
    <origin rpy="1.570795 3.14159 3.14159" xyz="0.0 0.0996 0.0"/>
    <axis xyz="0 0 1"/>
    <limit effort="28.0" lower="-6.28318" upper="6.28318" velocity="6.28"/>
    <dynamics damping="0.0" friction="0.0"/>
    <!-- <dynamics damping="${joint_damping}" friction="${joint_friction}"/> -->
  </joint>
  <link name="rb_kairos_ur16e_wrist_3_link">
    <visual>
      <origin rpy="1.570795 0 0" xyz="0 0 -0.0989"/>
      <geometry>
        <mesh filename="package://hrii_universal_robots_description/meshes/ur5e/visual/wrist3.dae"/>
      </geometry>
      <material name="LightGrey">
        <color rgba="0.7 0.7 0.7 1.0"/>
      </material>
    </visual>
    <collision>
      <origin rpy="1.5707963267948966 0 0" xyz="0 0 -0.0989"/>
      <geometry>
        <mesh filename="package://hrii_universal_robots_description/meshes/ur5e/collision/wrist3.stl"/>
      </geometry>
    </collision>
    <inertial>
      <mass value="0.1879"/>
      <origin rpy="0 0 0" xyz="0.0 0.0 -0.025"/>
      <inertia ixx="0.00013427015462525002" ixy="0.0" ixz="0.0" iyy="0.00013427015462525002" iyz="0.0" izz="0.00019024874999999997"/>
    </inertial>
  </link>
  <!-- ROS base_link to UR 'Base' Coordinates transform -->
  <link name="rb_kairos_ur16e_base"/>
  <joint name="rb_kairos_ur16e_base_link-base_fixed_joint" type="fixed">
    <!-- NOTE: this rotation is only needed as long as base_link itself is
                 not corrected wrt the real robot (ie: rotated over 180
                 degrees)
      -->
    <origin rpy="0 0 -3.14159" xyz="0 0 0"/>
    <parent link="rb_kairos_ur16e_base_link"/>
    <child link="rb_kairos_ur16e_base"/>
  </joint>
  <!-- Frame coincident with all-zeros TCP on UR controller -->
  <!-- Set this joint as revolute to use the FT gazebo plugin -->
  <!-- The mass and the inertia are required to not let the simulation crash -->
  <!-- <link name="${prefix}tool0">
      <xacro:cylinder_inertial radius="0.045" length="0.05" mass="${wrist_3_mass}">
        <origin xyz="0.0 0 0.0" rpy="0 0 0" />
      </xacro:cylinder_inertial>
    </link> -->
  <!-- <joint name="${prefix}wrist_3_link_tool0_fixed_joint" type="fixed">
      <origin xyz="0 ${wrist_3_length} 0" rpy="${PI/-2.0} 0 0"/>
      <parent link="${prefix}wrist_3_link"/>
      <child link="${prefix}tool0"/>
      <limit velocity="6.5" effort="1000" lower="0" upper="0" />
    </joint> -->
  <link name="rb_kairos_ur16e_flange">
    <inertial>
      <mass value="0.1879"/>
      <origin rpy="0 0 0" xyz="0.0 0 0.0"/>
      <inertia ixx="0.00013427015462525002" ixy="0.0" ixz="0.0" iyy="0.00013427015462525002" iyz="0.0" izz="0.00019024874999999997"/>
    </inertial>
  </link>
  <!-- <joint name="${prefix}wrist_3_link_tool0_fixed_joint" type="revolute">
      <origin xyz="0 ${wrist_3_length} 0" rpy="${PI/-2.0} 0 0"/>
      <parent link="${prefix}wrist_3_link"/>
      <child link="${prefix}tool0"/>
      <limit lower="0" upper="0" effort="1000" velocity="100"/>
      <axis xyz="0 0 1" />
    </joint> -->
  <joint name="rb_kairos_ur16e_wrist_3_link_flange_fixed_joint" type="fixed">
    <origin rpy="0 0 0" xyz="0 0 0"/>
    <parent link="rb_kairos_ur16e_wrist_3_link"/>
    <child link="rb_kairos_ur16e_flange"/>
  </joint>
  <joint name="rb_kairos_joint_ur16e_link0_base_footprint" type="fixed">
    <parent link="rb_kairos_base_chapa"/>
    <child link="rb_kairos_ur16e_base_link"/>
    <origin rpy="0 0 0" xyz="0.15887 0.0 0.18062"/>
  </joint>
  <!-- ******* -->
  <!-- Gripper -->
  <!-- ******* -->
  <!-- This file unifies all sensors that can be used on simulation, defined as xacro:macros -->
  <link name="rb_kairos_ur16e_EE"/>
  <joint name="rb_kairos_ur16e_joint_EE" type="fixed">
    <origin rpy="0 0 0" xyz="0 0 0"/>
    <parent link="rb_kairos_ur16e_flange"/>
    <child link="rb_kairos_ur16e_EE"/>
    <axis xyz="0 0 0"/>
  </joint>
  <!-- *********** -->
  <!-- Pole camera -->
  <!-- *********** -->
  <!-- ************ -->
  <!-- Base Plugins -->
  <!-- ************ -->
  <gazebo>
    <plugin filename="libgazebo_ros_control.so" name="ros_control">
      <!--<robotNamespace>/summit_xl</robotNamespace>-->
      <robotParam>robot_description</robotParam>
      <controlPeriod>0.001</controlPeriod>
      <robotSimType>gazebo_ros_control/DefaultRobotHWSim</robotSimType>
      <legacyModeNS>true</legacyModeNS>
    </plugin>
  </gazebo>
  <!-- <xacro:if value="$(arg base_gazebo_ros_control)">
        <xacro:ros_control/>
        <gazebo>
            <plugin name="${arm_prefix}ros_control" filename="libgazebo_ros_control.so">
                
                <robotSimType>gazebo_ros_control/DefaultRobotHWSim</robotSimType>
                <legacyModeNS>true</legacyModeNS>
                <updateRate>1000.0</updateRate>
            </plugin>
        </gazebo>
    </xacro:if> -->
  <transmission name="rb_kairos_ur16e_shoulder_pan_trans">
    <type>transmission_interface/SimpleTransmission</type>
    <joint name="rb_kairos_ur16e_shoulder_pan_joint">
      <hardwareInterface>position</hardwareInterface>
    </joint>
    <actuator name="rb_kairos_ur16e_shoulder_pan_motor">
      <hardwareInterface>position</hardwareInterface>
      <mechanicalReduction>1</mechanicalReduction>
    </actuator>
  </transmission>
  <transmission name="rb_kairos_ur16e_shoulder_lift_trans">
    <type>transmission_interface/SimpleTransmission</type>
    <joint name="rb_kairos_ur16e_shoulder_lift_joint">
      <hardwareInterface>position</hardwareInterface>
    </joint>
    <actuator name="rb_kairos_ur16e_shoulder_lift_motor">
      <hardwareInterface>position</hardwareInterface>
      <mechanicalReduction>1</mechanicalReduction>
    </actuator>
  </transmission>
  <transmission name="rb_kairos_ur16e_elbow_trans">
    <type>transmission_interface/SimpleTransmission</type>
    <joint name="rb_kairos_ur16e_elbow_joint">
      <hardwareInterface>position</hardwareInterface>
    </joint>
    <actuator name="rb_kairos_ur16e_elbow_motor">
      <hardwareInterface>position</hardwareInterface>
      <mechanicalReduction>1</mechanicalReduction>
    </actuator>
  </transmission>
  <transmission name="rb_kairos_ur16e_wrist_1_trans">
    <type>transmission_interface/SimpleTransmission</type>
    <joint name="rb_kairos_ur16e_wrist_1_joint">
      <hardwareInterface>position</hardwareInterface>
    </joint>
    <actuator name="rb_kairos_ur16e_wrist_1_motor">
      <hardwareInterface>position</hardwareInterface>
      <mechanicalReduction>1</mechanicalReduction>
    </actuator>
  </transmission>
  <transmission name="rb_kairos_ur16e_wrist_2_trans">
    <type>transmission_interface/SimpleTransmission</type>
    <joint name="rb_kairos_ur16e_wrist_2_joint">
      <hardwareInterface>position</hardwareInterface>
    </joint>
    <actuator name="rb_kairos_ur16e_wrist_2_motor">
      <hardwareInterface>position</hardwareInterface>
      <mechanicalReduction>1</mechanicalReduction>
    </actuator>
  </transmission>
  <transmission name="rb_kairos_ur16e_wrist_3_trans">
    <type>transmission_interface/SimpleTransmission</type>
    <joint name="rb_kairos_ur16e_wrist_3_joint">
      <hardwareInterface>position</hardwareInterface>
    </joint>
    <actuator name="rb_kairos_ur16e_wrist_3_motor">
      <hardwareInterface>position</hardwareInterface>
      <mechanicalReduction>1</mechanicalReduction>
    </actuator>
  </transmission>
  <transmission name="rb_kairos_ur16e_wrist_3_link_flange_trans">
    <type>transmission_interface/SimpleTransmission</type>
    <joint name="rb_kairos_ur16e_wrist_3_link_flange_fixed_joint">
      <hardwareInterface>position</hardwareInterface>
    </joint>
    <actuator name="rb_kairos_ur16e_wrist_3_link_flange_motor">
      <hardwareInterface>position</hardwareInterface>
      <mechanicalReduction>1</mechanicalReduction>
    </actuator>
  </transmission>
  <gazebo reference="rb_kairos_ur16e_base_link">
    <selfCollide>False</selfCollide>
    <mu1>0.2</mu1>
    <mu2>0.2</mu2>
    <minDepth>0.001</minDepth>
    <maxVel>0</maxVel>
  </gazebo>
  <gazebo reference="rb_kairos_ur16e_shoulder_link">
    <selfCollide>False</selfCollide>
    <mu1>0.2</mu1>
    <mu2>0.2</mu2>
  </gazebo>
  <gazebo reference="rb_kairos_ur16e_upper_arm_link">
    <selfCollide>False</selfCollide>
    <mu1>0.2</mu1>
    <mu2>0.2</mu2>
  </gazebo>
  <gazebo reference="rb_kairos_ur16e_forearm_link">
    <selfCollide>False</selfCollide>
    <mu1>0.2</mu1>
    <mu2>0.2</mu2>
  </gazebo>
  <gazebo reference="rb_kairos_ur16e_wrist_1_link">
    <selfCollide>False</selfCollide>
    <mu1>0.2</mu1>
    <mu2>0.2</mu2>
  </gazebo>
  <gazebo reference="rb_kairos_ur16e_wrist_3_link">
    <selfCollide>False</selfCollide>
    <mu1>0.2</mu1>
    <mu2>0.2</mu2>
  </gazebo>
  <gazebo reference="rb_kairos_ur16e_wrist_2_link">
    <selfCollide>False</selfCollide>
    <mu1>0.2</mu1>
    <mu2>0.2</mu2>
  </gazebo>
  <gazebo reference="rb_kairos_ur16e_ee_link">
    <selfCollide>False</selfCollide>
    <mu1>0.2</mu1>
    <mu2>0.2</mu2>
  </gazebo>
  <gazebo reference="rb_kairos_ur16e_shoulder_pan_joint">
    <implicitSpringDamper>1</implicitSpringDamper>
    <provideFeedback>true</provideFeedback>
  </gazebo>
  <gazebo reference="rb_kairos_ur16e_shoulder_lift_joint">
    <implicitSpringDamper>1</implicitSpringDamper>
    <provideFeedback>true</provideFeedback>
  </gazebo>
  <gazebo reference="rb_kairos_ur16e_elbow_joint">
    <implicitSpringDamper>1</implicitSpringDamper>
    <provideFeedback>true</provideFeedback>
  </gazebo>
  <gazebo reference="rb_kairos_ur16e_wrist_1_joint">
    <implicitSpringDamper>1</implicitSpringDamper>
    <provideFeedback>true</provideFeedback>
  </gazebo>
  <gazebo reference="rb_kairos_ur16e_wrist_2_joint">
    <implicitSpringDamper>1</implicitSpringDamper>
    <provideFeedback>true</provideFeedback>
  </gazebo>
  <gazebo reference="rb_kairos_ur16e_wrist_3_joint">
    <implicitSpringDamper>1</implicitSpringDamper>
    <provideFeedback>true</provideFeedback>
  </gazebo>
  <gazebo reference="rb_kairos_ur16e_wrist_3_link_flange_fixed_joint">
    <implicitSpringDamper>1</implicitSpringDamper>
    <provideFeedback>true</provideFeedback>
  </gazebo>
  <gazebo>
    <plugin filename="libgazebo_ros_ft_sensor.so" name="rb_kairos_ur16e_flange_ft_sensor">
      <updateRate>100.0</updateRate>
      <!-- <topicName>${prefix}/ft_sensor</topicName> -->
      <topicName>wrench</topicName>
      <jointName>rb_kairos_ur16e_wrist_3_link_flange_fixed_joint</jointName>
    </plugin>
  </gazebo>
  <!-- **************** -->
  <!-- FT sensor plugin -->
  <!-- **************** -->
  <gazebo>
    <plugin filename="libgazebo_ros_ft_sensor.so" name="rb_kairos_ur16e_flange_ft_sensor">
      <updateRate>100.0</updateRate>
      <topicName>ur16e_ft_sensor</topicName>
      <jointName>rb_kairos_ur16e_wrist_3_link_flange_fixed_joint</jointName>
    </plugin>
  </gazebo>
  <link name="world"/>
  <joint name="reference" type="floating">
    <parent link="world"/>
    <child link="rb_kairos_base_footprint"/>
  </joint>
</robot>

